<?xml version="1.0" encoding="UTF-8"?>
<sdf version='1.6'>
  <model name='prismatic_box'>
    <link name='world_box'>
      <pose frame=''>0 0 1 0 -0 0</pose>
      <inertial>
        <pose frame=''>0 0 0.113636 0 -0 0</pose>
        <mass>5.5e+06</mass>
        <inertia>
          <ixx>9.0054e+07</ixx>
          <ixy>0</ixy>
          <ixz>0</ixz>
          <iyy>1.14822e+09</iyy>
          <iyz>0</iyz>
          <izz>1.2335e+09</izz>
        </inertia>
      </inertial>
      <collision name='world_box_collision'>
        <pose frame=''>0 0 0 0 -0 0</pose>
        <geometry>
          <box>
            <size>50 14 2</size>
          </box>
        </geometry>
        <surface>
          <contact>
            <ode/>
          </contact>
          <friction>
            <ode/>
          </friction>
        </surface>
      </collision>
      <collision name='world_box_fixed_joint_lump__slide_box_collision_1'>
        <pose frame=''>0 0 1.25 0 -0 0</pose>
        <geometry>
          <box>
            <size>50 12 0.5</size>
          </box>
        </geometry>
        <surface>
          <contact>
            <ode/>
          </contact>
          <friction>
            <ode/>
          </friction>
        </surface>
      </collision>
      <visual name='world_box_visual'>
        <pose frame=''>0 0 0 0 -0 0</pose>
        <geometry>
          <box>
            <size>50 14 2</size>
          </box>
        </geometry>
        <material>
          <script>
            <name>Gazebo/Gray</name>
            <uri>file://media/materials/scripts/gazebo.material</uri>
          </script>
        </material>
      </visual>
      <visual name='world_box_fixed_joint_lump__slide_box_visual_1'>
        <pose frame=''>0 0 1.25 0 -0 0</pose>
        <geometry>
          <box>
            <size>50 12 0.5</size>
          </box>
        </geometry>
        <material>
          <script>
            <name>Gazebo/Blue</name>
            <uri>file://media/materials/scripts/gazebo.material</uri>
          </script>
        </material>
      </visual>
      <velocity_decay/>
      <gravity>1</gravity>
      <velocity_decay/>
    </link>
    <joint name='world_box_joint' type='fixed'>
      <child>world_box</child>
      <parent>world</parent>
    </joint>
    <link name='box'>
      <pose frame=''>0 0 7.45 0 -0 0</pose>
      <inertial>
        <pose frame=''>0 0 0 0 -0 0</pose>
        <mass>15000</mass>
        <inertia>
          <ixx>250000</ixx>
          <ixy>0</ixy>
          <ixz>0</ixz>
          <iyy>1.25e+06</iyy>
          <iyz>0</iyz>
          <izz>1.25e+06</izz>
        </inertia>
      </inertial>
      <collision name='box_fixed_joint_lump__collision_collision'>
        <pose frame=''>0 0 0 0 -0 0</pose>
        <geometry>
          <mesh>
            <scale>1 1 1</scale>
            <uri>model://gazebo_sim_models/models/prism/prism.dae</uri>
          </mesh>
        </geometry>
      </collision>
      <visual name='box_fixed_joint_lump__visual_visual'>
        <pose frame=''>0 0 0 0 -0 0</pose>
        <geometry>
          <mesh>
            <scale>1 1 1</scale>
            <uri>model://gazebo_sim_models/models/prism/prism.dae</uri>
          </mesh>
        </geometry>
      </visual>
    </link>
    <joint name='box_joint' type='prismatic'>
      <child>box</child>
      <parent>world_box</parent>
      <axis>
        <xyz>1 0 0</xyz>
        <limit>
          <lower>-25</lower>
          <upper>25</upper>
          <effort>1e+08</effort>
          <velocity>200</velocity>
        </limit>
        <dynamics>
          <spring_reference>0</spring_reference>
          <spring_stiffness>0</spring_stiffness>
        </dynamics>
        <use_parent_model_frame>0</use_parent_model_frame>
      </axis>
    </joint>
    <static>0</static>
    <plugin name='gazebo_ros_control' filename='libgazebo_ros_control.so'>
      <robotNamespace>/prismatic_box_controller</robotNamespace>
      <robotSimType>gazebo_ros_control/DefaultRobotHWSim</robotSimType>
      <legacyModeNS>1</legacyModeNS>
    </plugin>
  </model>
</sdf>
