<?xml version="1.0" encoding="UTF-8"?>
<robot name="prismatic_box">
	
	<gazebo>
		<plugin name="gazebo_ros_control" filename="libgazebo_ros_control.so">
			<robotNamespace>/prismatic_box_controller</robotNamespace>
			<robotSimType>gazebo_ros_control/DefaultRobotHWSim</robotSimType>
			<legacyModeNS>true</legacyModeNS>
		</plugin>
	</gazebo>

	<link name="world"/>

	<link name="world_box">
		<inertial>
			<mass value="5000000" />
			<origin xyz="0 0 0.0" />
			<inertia ixx="83333333" ixy="0.0" ixz="0.0" iyy="1043333333" iyz="0.0" izz="1123333333" /> 
			<!--Ixx = 1/12/m*(y^2+z^2)-->
		</inertial>

		<visual>
			<origin xyz="0 0 0"  />
			<geometry>
				<box size="50 14 2" />
			</geometry>
		</visual>

		<collision>
			<origin xyz="0 0 0" />
			<geometry>
				<box size="50 14 2" />
			</geometry>
		</collision>
	</link>	
	<gazebo reference="world_box">
		<material>Gazebo/Gray</material>
	</gazebo>

	<joint name="world_box_joint" type="fixed">
		<origin xyz="0 0 1.0" rpy="0 0 0" />
		<parent link="world"/>
		<child link="world_box" />
	</joint>

	<link name="slide_box">
		<inertial>
			<mass value="500000" />
			<origin xyz="0 0 0" />
			<inertia ixx="6010416" ixy="0.0" ixz="0.0" iyy="104177083" iyz="0.0" izz="110166666" /> 
			<!--Ixx = 1/12/m*(y^2+z^2)-->
		</inertial>

		<visual>
			<origin xyz="0 0 0" />
			<geometry>
				<box size="50 12 0.5" />
			</geometry>
		</visual>

		<collision>
			<origin xyz="0 0 0" />
			<geometry>
				<box size="50 12 0.5" />
			</geometry>
			<!--surface>
				<friction>
				  <ode>
					<mu>0.0</mu>
					<mu2>0.0</mu2>
				  </ode>
				</friction>
			</surface-->
		</collision>
	</link>	
	<gazebo reference="slide_box">
		<material>Gazebo/Blue</material>
	</gazebo>

	<joint name="slide_box_joint" type="fixed">
		<origin xyz="0 0 1.25" rpy="0 0 0" />
		<parent link="world_box"/>
		<child link="slide_box" />
	</joint>

	<link name="box">
        <inertial>
			<mass value="15000" />
			<origin xyz="0 0 0" />
			<inertia ixx="250000" ixy="0.0" ixz="0.0" iyy="1250000" iyz="0.0" izz="1250000" /> 
			<!--Ixx = 1/12/m*(y^2+z^2)-->
        </inertial>

		<visual name='visual'>
          <geometry>
            <!--mesh>
              <uri>model://granite_dell_terrain/pbr-less-1.dae</uri>
            </mesh-->
			<mesh filename="package://gazebo_sim_models/models/prism/prism.dae"/>
          </geometry>
        </visual>

        <collision name='collision'>
		  <origin xyz="0 0 0" />
          <surface>
				<friction>
				  <bullet>
					<friction>1000</friction>
					<friction2>1000</friction2>
					<rolling_friction>1000</rolling_friction>
				  </bullet>
                  <ode>
					<mu>1000</mu>
				    <mu2>1000</mu2>
				    <fdir1>1 0 0</fdir1>
			        <slip1>0</slip1>
			        <slip2>0</slip2>
				  </ode>
				</friction>
				<contact>
					<ode>
						<min_depth>0.003</min_depth>
					</ode>
				</contact>
				<bounce>
            		<restitution_coefficient>0.8</restitution_coefficient>
            		<threshold>0.1</threshold>
          		</bounce>
		  </surface>
          <geometry>
            <mesh filename="package://gazebo_sim_models/models/prism/prism.dae"/>
          </geometry>
        </collision>
	</link>


	<joint name="box_joint" type="prismatic">
		<origin xyz="0 0 5.2" rpy="0 0 0" />
		<parent link="slide_box"/>
		<child link="box" />
        <xis xyz = "1 0 0"/>
		<limit effort="100000000" lower="-25" upper="25" velocity="200" />
	</joint>

	

    <transmission name="tran1">
        <type>transmission_interface/SimpleTransmission</type>
        <joint name="box_joint">
            <hardwareInterface>hardware_interface/EffortJointInterface</hardwareInterface>
        </joint>
        <actuator name="motor1">
            <hardwareInterface>hardware_interface/EffortJointInterface</hardwareInterface>
            <mechanicalReduction>1</mechanicalReduction>
        </actuator>
    </transmission>


</robot>


